Workbook

Sheet Guia
A1: Para qué sirve | B1: Calificar cada respuesta POR AFIRMACIÓN (hoja Afirmaciones). N2, N3, códigos, alertas y diagnóstico se calculan solos en Respuestas. Reglas completas: protocol_v2.md §3-§5.
A2: Colores | B2: Amarillo = lo escribes o eliges tú. Verde = automático (no editable). Gris = dato de la pregunta/corrida.
A3: Flujo | B3: 1) En Respuestas, lee pregunta, referencia y respuesta del sistema (en RAG, los fragmentos están en Contextos). 2) En Afirmaciones, una fila por afirmación (máx. ~6): qid, modo, texto, tipo, vs_ref, hecho_ref, zona, respaldo, cita_n, fragmento_sostiene. 3) Revisa la columna 'chequeo'. 4) Revisa 'llegó' en Hechos (sobre todo ALT-P). 5) Lee N2/N3/alertas/diagnóstico en Respuestas.
A4: tipo | B4: hecho = afirma algo. abstencion = dice que el contexto o el modelo no tiene la información ('los pasajes no dicen...'). Afirmar que ATT&CK no documenta algo ('ATT&CK no lista...') es un HECHO y puede ser INCORRECTA.
A5: vs_ref | B5: CORRECTA = coincide con la referencia (en una abstención: se abstiene donde debía). INCORRECTA = contradice la referencia (en una abstención: niega algo que la referencia sí contiene). FUERA_REF = ni confirma ni contradice la referencia.
A6: hecho_ref | B6: H# de la hoja Hechos que cubre una afirmación CORRECTA; varios separados por ';' (ej. H2;H3). En INCORRECTA/abstención es opcional (nota).
A7: zona | B7: ref (por defecto) o no_resp si responde a la parte NO respondible. Un hecho FUERA_REF en no_resp genera NO-ABS.
A8: respaldo (solo RAG, solo hecho) | B8: SOSTENIDA = tiene cita [n] y ese fragmento expresa la relación. CITA-X = cita pero ese fragmento no la sostiene. SIN-CITA = sin cita, pero algún fragmento recibido la sostiene. SIN-RESPALDO = ningún fragmento recibido la sostiene (tenga o no cita). Dos nombres en la misma lista no sostienen 'A usa B'.
A9: llegó (hoja Hechos) | B9: Prellenado desde evidence_check.py: SI = llegó un fragmento gold; ALT = llegó evidencia alternativa; ALT-P = solo evidencia parcial (cuenta como NO salvo que la cambies a ALT y lo justifiques en comentario); NO = no llegó. Verifica leyendo Contextos.
A10: Códigos | B10: INC, ABS-E, NO-ABS, SIN-R, CITA-X, SIN-C se derivan de las columnas. Omisiones = hechos de la referencia sin cubrir (cubierto = 0).
A11: N2 | B11: H=0: 2 si no hay NO-ABS, si no 0. H>0: 2 si cubre todos y no hay INC/ABS-E/NO-ABS; 0 si no cubre ninguno; 1 en los demás casos. Sin topes.
A12: N3 | B12: Solo RAG, sobre afirmaciones de hecho: 2 todas sostenidas; 0 ninguna; 1 parcial; N/A sin afirmaciones de hecho.
... A16: Verificación | B16: Las fórmulas se evaluaron con un motor independiente (librería Python 'formulas') sobre calificacion_v2_DEMO.xlsx, que trae las 27 afirmaciones de los ejemplos: N2, N3, alertas y diagnóstico de las 8 respuestas coinciden con la columna 'esperado' de Respuestas. No se han abierto todavía en Excel; si algo no calcula en tu Excel, avísalo.

Sheet Respuestas
A1: qid | B1: modo | C1: idioma | D1: N0 corpus | E1: pregunta | F1: respuesta de referencia | G1: parte NO respondible | H1: RESPUESTA DEL SISTEMA | I1: truncada | J1: N1 (auto) | K1: hechos llegaron (auto) | L1: n afirm. | M1: hechos H | N1: cubiertos C | O1: cobertura | P1: INC | Q1: ABS-E | R1: NO-ABS | S1: FUERA_REF | T1: SIN-R | U1: CITA-X | V1: SIN-C | W1: afirm. de hecho | X1: de hecho sostenidas | Y1: N2 | Z1: N3 | AA1: alertas | AB1: diagnóstico (lista) | AC1: primer eslabón | AD1: precisión citas | AE1: cobertura citas | AF1: aux E1 | AG1: aux E2 | AH1: comentario | AI1: ESPERADO (ejemplos): N2 | N3 | diagnóstico
A2: p01 | B2: rag | C2: ES | D2: completa | E2: ¿Qué mitigaciones propone ATT&CK para la sub-técnica T1059.001 PowerShell y en qué consiste cada una? | F2: ATT&CK lista cinco mitigaciones para T1059.001: M1038 Execution Prevention (control de aplicaciones y PowerShell Constrained Language Mode), M1045 Code Signing (política de ejecución sólo de scripts firmados), M1026 Privileged Account Management (restringir la ejecución a administradores; JEA para limitar comandos), M1049 Antivirus/Antimalware (cuarentena automática de archivos sospechosos) y M1042 Disable or Remove Feature or Program (eliminar PowerShell donde no se necesite y deshabilitar/restringir WinRM). | H2: No se proporciona información en los contextos pasados sobre mitigaciones específicas para la sub-técnica T1059.001 PowerShell. Por lo tanto, no se puede responder a la pregunta con base en los datos ofrecidos. | I2: NO | J2: NINGUNA | K2: 0/5 | L2: =COUNTIFS(Afirmaciones!$A$2:$A$401,$A2,Afirmaciones!$B$2:$B$401,$B2) -> 1 | M2: =COUNTIFS(Hechos!$A$2:$A$201,$A2) -> 5 | N2: =IF($B2="rag",SUMIFS(Hechos!$F$2:$F$201,Hechos!$A$2:$A$201,$A2),SUMIFS(Hechos!$G$2:$G$201,Hechos!$A$2:$A$201,$A2)) -> 0 | O2: =IF($M2=0,"-",$N2&"/"&$M2) -> 0/5 | P2: =COUNTIFS(Afirmaciones!$A$2:$A$401,$A2,Afirmaciones!$B$2:$B$401,$B2,Afirmaciones!$E$2:$E$401,"hecho",Afirmaciones!$F$2:$F$401,"INCORRECTA") -> 0 | Q2: =COUNTIFS(Afirmaciones!$A$2:$A$401,$A2,Afirmaciones!$B$2:$B$401,$B2,Afirmaciones!$E$2:$E$401,"abstencion",Afirmaciones!$F$2:$F$401,"INCORRECTA") -> 1 | R2: =COUNTIFS(Afirmaciones!$A$2:$A$401,$A2,Afirmaciones!$B$2:$B$401,$B2,Afirmaciones!$E$2:$E$401,"hecho",Afirmaciones!$F$2:$F$401,"FUERA_REF",Afirmaciones!$H$2:$H$401,"no_resp") -> 0 | S2: =COUNTIFS(Afirmaciones!$A$2:$A$401,$A2,Afirmaciones!$B$2:$B$401,$B2,Afirmaciones!$E$2:$E$401,"hecho",Afirmaciones!$F$2:$F$401,"FUERA_REF") -> 0 | T2: =COUNTIFS(Afirmaciones!$A$2:$A$401,$A2,Afirmaciones!$B$2:$B$401,$B2,Afirmaciones!$E$2:$E$401,"hecho",Afirmaciones!$I$2:$I$401,"SIN-RESPALDO") -> 0 | U2: =COUNTIFS(Afirmaciones!$A$2:$A$401,$A2,Afirmaciones!$B$2:$B$401,$B2,Afirmaciones!$E$2:$E$401,"hecho",Afirmaciones!$I$2:$I$401,"CITA-X") -> 0 | V2: =COUNTIFS(Afirmaciones!$A$2:$A$401,$A2,Afirmaciones!$B$2:$B$401,$B2,Afirmaciones!$E$2:$E$401,"hecho",Afirmaciones!$I$2:$I$401,"SIN-CITA") -> 0 | W2: =COUNTIFS(Afirmaciones!$A$2:$A$401,$A2,Afirmaciones!$B$2:$B$401,$B2,Afirmaciones!$E$2:$E$401,"hecho") -> 0 | X2: =COUNTIFS(Afirmaciones!$A$2:$A$401,$A2,Afirmaciones!$B$2:$B$401,$B2,Afirmaciones!$E$2:$E$401,"hecho",Afirmaciones!$I$2:$I$401,"SOSTENIDA") -> 0 | Y2: =IF($L2=0,"",IF($M2=0,IF($R2>0,0,2),IF(AND($N2=$M2,$P2+$Q2+$R2=0),2,IF($N2=0,0,1)))) -> 0 | Z2: =IF($L2=0,"",IF($B2="llm","N/A",IF($W2=0,"N/A",IF($X2=$W2,2,IF($X2=0,0,1))))) -> N/A | AA2: =IF($L2=0,"",IF(AND($P2+$Q2+$R2=0,$T2+$U2=0,$I2<>"SI"),"-",TRIM(IF($P2+$Q2+$R2>0,"CRITICA ","")&IF($T2+$U2>0,"RESPALDO ","")&IF($I2="SI","TRUNC","")))) -> CRITICA | AB2: =IF($L2=0,"",IF(AND($R2=0,$AF2=0,$AG2=0,$P2+$Q2=0,$T2+$U2+$V2=0),"OK",TRIM(IF($R2>0,"E0 ","")&IF($AF2>0,"E1 ","")&IF(OR($AG2>0,AND($P2+$Q2>0,$AF2=0)),"E2 ","")&IF($T2+$U2+$V2>0,"E3 ","")))) -> E1 | AC2: =IF($AB2="","",IF($AB2="OK","OK",LEFT($AB2,2))) -> E1 | AD2: =IF(OR($L2=0,$B2="llm",$W2=0),"-",$X2&"/"&$W2) -> - | AE2: =IF(OR($L2=0,$B2<>"rag",$M2=0),"-",SUMIFS(Hechos!$H$2:$H$201,Hechos!$A$2:$A$201,$A2)&"/"&$M2) -> 0/5 | AF2: =IF($B2="rag",SUMPRODUCT((Hechos!$A$2:$A$201=$A2)*(Hechos!$F$2:$F$201=0)*((Hechos!$E$2:$E$201="NO")+(Hechos!$E$2:$E$201="ALT-P")+(Hechos!$E$2:$E$201=""))),0) -> 5 | AG2: =IF($B2="rag",SUMPRODUCT((Hechos!$A$2:$A$201=$A2)*(Hechos!$F$2:$F$201=0)*((Hechos!$E$2:$E$201="SI")+(Hechos!$E$2:$E$201="ALT"))),$M2-$N2) -> 0 | AI2: 0 | N/A | E1
A3: p01 | B3: llm | C3: ES | D3: completa | E3: ¿Qué mitigaciones propone ATT&CK para la sub-técnica T1059.001 PowerShell y en qué consiste cada una? | F3: ATT&CK lista cinco mitigaciones para T1059.001: M1038 Execution Prevention (control de aplicaciones y PowerShell Constrained Language Mode), M1045 Code Signing (política de ejecución sólo de scripts firmados), M1026 Privileged Account Management (restringir la ejecución a administradores; JEA para limitar comandos), M1049 Antivirus/Antimalware (cuarentena automática de archivos sospechosos) y M1042 Disable or Remove Feature or Program (eliminar PowerShell donde no se necesite y deshabilitar/restringir WinRM). | H3: La sub-técnica **T1059.001** de ATT&CK se refiere a **"Command and Scripting Interpreter"** con el enfoque específico de **PowerShell** (uso de PowerShell para ejecutar comandos y scripts). Aunque ATT&CK no proporciona una lista detallada de "mitigaciones" en el sentido de soluciones técnicas específicas para cada sub-técnica, sí ofrece **recomendaciones de mitigación** basadas en buenas prácticas de seguridad y en el contexto de detección y prevención. A continuación, se presentan las **mitigaciones propuestas o recomendadas** para T1059.001 (PowerShell), junto con una explicación de cada una: --- ### 1. **Restricción de ejecución de PowerShell** - **Qué consiste**: Limitar el uso de PowerShell a entornos de ejecución seguros (por ejemplo, solo en modo "Restricted" o "RemoteSigned") y evitar que se ejecute scripts no firmados. - **Por qué ayuda**: El modo "Restricted" bloquea la ejecución de scripts, lo que impide que un atacante ejecute código malicioso a través de PowerShell. - **Ejemplo**: Configurar el registro de Windows para que PowerShell solo permita comandos interactivos y no scripts. --- ### 2. **Uso de firmas digitales y validación de scripts** - **Qué consiste**: Requerir que los scripts PowerShell estén firmados por un certificado de firma válida antes de que se ejecuten. - **Por qué ayuda**: Los scripts firmados son más fáciles de verificar y reducen el riesgo de ejecutar código malicioso. - **Ejemplo**: Configurar el sistema para que solo se permita la ejecución de scripts firmados (usando el parámetro `-ExecutionPolicy` en PowerShell). --- ### 3. **Monitoreo y auditoría de comandos PowerShell** - **Qué consiste**: Implementar herramientas de detección que monitoren los comandos ejecutados en PowerShell (por ejemplo, registros de eventos del sistema). - **Por qué ayuda**: Permite detectar comportamientos sospechosos, como comandos que no son típicos de uso normal. - **Ejemplo**: Usar herramientas como **Windows Event Logs (Event ID 4688)** o **SIEM** (como Splunk, QRadar) para analizar comandos ejecutados. --- ### 或 4. **Detección de comportamientos anómalos** - **Qué consiste**: Aplicar análisis de comportamiento para detectar actividades inusuales, como la ejecución de comandos en horarios fuera de lo normal o en entornos no autorizados. - **Por qué ayuda**: Aunque el atacante pueda ejecutar PowerShell, su comportamiento puede ser detectado como anómalo. - **Ejemplo**: Detección de comandos como `Invoke-Expression`, `IEX`, o `System.Net.WebClient` que se usan comúnmente en ataques. --- ### 5. **Control de acceso y políticas de grupo (Group Policy)** - **Qué consiste**: Aplicar políticas de grupo que limiten el acceso a PowerShell y a los permisos de ejecución. - **Por qué ayuda**: Reduce el riesgo de que usuarios no autorizados o maliciosos puedan ejecutar PowerShell. - **Ejemplo**: Configurar políticas de grupo para que solo los usuarios autorizados puedan ejecutar PowerShell. --- ### 6. **Uso de alternativas seguras a PowerShell** - **Qué consiste**: En entornos críticos, usar herramientas más seguras como **Windows Command Prompt**, **batch files**, o **PowerShell con ejecución restringida**. - **Por qué ayuda**: Reduce la superficie de ataque al evitar el uso de PowerShell en entornos sensibles. --- ### Nota importante: ATT&CK no proporciona una lista oficial de "mitigaciones" como un documento técnico detallado. Las mencionadas anteriormente son **recomendaciones basadas en buenas prácticas de seguridad** y en el marco de la estrategia de mitigación de la sub-técnica T1059.001. --- ✅ **Resumen**: | Mitigación | Descripción | |----------|-------------| | Restricción de ejecución | Usar modos seguros (ej. Restricted) en PowerShell | | Firmas digitales | Requerir firmas válidas para scripts | | Monitoreo de eventos | Auditar comandos ejecutados en PowerShell | I3: SI | L3: =COUNTIFS(Afirmaciones!$A$2:$A$401,$A3,Afirmaciones!$B$2:$B$401,$B3) -> 6 | M3: =COUNTIFS(Hechos!$A$2:$A$201,$A3) -> 5 | N3: =IF($B3="rag",SUMIFS(Hechos!$F$2:$F$201,Hechos!$A$2:$A$201,$A3),SUMIFS(Hechos!$G$2:$G$201,Hechos!$A$2:$A$201,$A3)) -> 2 | O3: =IF($M3=0,"-",$N3&"/"&$M3) -> 2/5 | P3: =COUNTIFS(Afirmaciones!$A$2:$A$401,$A3,Afirmaciones!$B$2:$B$401,$B3,Afirmaciones!$E$2:$E$401,"hecho",Afirmaciones!$F$2:$F$401,"INCORRECTA") -> 1 | Q3: =COUNTIFS(Afirmaciones!$A$2:$A$401,$A3,Afirmaciones!$B$2:$B$401,$B3,Afirmaciones!$E$2:$E$401,"abstencion",Afirmaciones!$F$2:$F$401,"INCORRECTA") -> 0 | R3: =COUNTIFS(Afirmaciones!$A$2:$A$401,$A3,Afirmaciones!$B$2:$B$401,$B3,Afirmaciones!$E$2:$E$401,"hecho",Afirmaciones!$F$2:$F$401,"FUERA_REF",Afirmaciones!$H$2:$H$401,"no_resp") -> 0 | S3: =COUNTIFS(Afirmaciones!$A$2:$A$401,$A3,Afirmaciones!$B$2:$B$401,$B3,Afirmaciones!$E$2:$E$401,"hecho",Afirmaciones!$F$2:$F$401,"FUERA_REF") -> 3 | T3: =COUNTIFS(Afirmaciones!$A$2:$A$401,$A3,Afirmaciones!$B$2:$B$401,$B3,Afirmaciones!$E$2:$E$401,"hecho",Afirmaciones!$I$2:$I$401,"SIN-RESPALDO") -> 0 | U3: =COUNTIFS(Afirmaciones!$A$2:$A$401,$A3,Afirmaciones!$B$2:$B$401,$B3,Afirmaciones!$E$2:$E$401,"hecho",Afirmaciones!$I$2:$I$401,"CITA-X") -> 0 | V3: =COUNTIFS(Afirmaciones!$A$2:$A$401,$A3,Afirmaciones!$B$2:$B$401,$B3,Afirmaciones!$E$2:$E$401,"hecho",Afirmaciones!$I$2:$I$401,"SIN-CITA") -> 0 | W3: =COUNTIFS(Afirmaciones!$A$2:$A$401,$A3,Afirmaciones!$B$2:$B$401,$B3,Afirmaciones!$E$2:$E$401,"hecho") -> 6 | X3: =COUNTIFS(Afirmaciones!$A$2:$A$401,$A3,Afirmaciones!$B$2:$B$401,$B3,Afirmaciones!$E$2:$E$401,"hecho",Afirmaciones!$I$2:$I$401,"SOSTENIDA") -> 0 | Y3: =IF($L3=0,"",IF($M3=0,IF($R3>0,0,2),IF(AND($N3=$M3,$P3+$Q3+$R3=0),2,IF($N3=0,0,1)))) -> 1 | Z3: =IF($L3=0,"",IF($B3="llm","N/A",IF($W3=0,"N/A",IF($X3=$W3,2,IF($X3=0,0,1))))) -> N/A | AA3: =IF($L3=0,"",IF(AND($P3+$Q3+$R3=0,$T3+$U3=0,$I3<>"SI"),"-",TRIM(IF($P3+$Q3+$R3>0,"CRITICA ","")&IF($T3+$U3>0,"RESPALDO ","")&IF($I3="SI","TRUNC","")))) -> CRITICA TRUNC | AB3: =IF($L3=0,"",IF(AND($R3=0,$AF3=0,$AG3=0,$P3+$Q3=0,$T3+$U3+$V3=0),"OK",TRIM(IF($R3>0,"E0 ","")&IF($AF3>0,"E1 ","")&IF(OR($AG3>0,AND($P3+$Q3>0,$AF3=0)),"E2 ","")&IF($T3+$U3+$V3>0,"E3 ","")))) -> E2 | AC3: =IF($AB3="","",IF($AB3="OK","OK",LEFT($AB3,2))) -> E2 | AD3: =IF(OR($L3=0,$B3="llm",$W3=0),"-",$X3&"/"&$W3) -> - | AE3: =IF(OR($L3=0,$B3<>"rag",$M3=0),"-",SUMIFS(Hechos!$H$2:$H$201,Hechos!$A$2:$A$201,$A3)&"/"&$M3) -> - | AF3: =IF($B3="rag",SUMPRODUCT((Hechos!$A$2:$A$201=$A3)*(Hechos!$F$2:$F$201=0)*((Hechos!$E$2:$E$201="NO")+(Hechos!$E$2:$E$201="ALT-P")+(Hechos!$E$2:$E$201=""))),0) -> 0 | AG3: =IF($B3="rag",SUMPRODUCT((Hechos!$A$2:$A$201=$A3)*(Hechos!$F$2:$F$201=0)*((Hechos!$E$2:$E$201="SI")+(Hechos!$E$2:$E$201="ALT"))),$M3-$N3) -> 3 | AI3: 1 | N/A | E2
A4: p02 | B4: rag | C4: EN | D4: completa | E4: According to ATT&CK, which tactic does Phishing (T1566) belong to and what are its four sub-techniques? | F4: Phishing belongs to the Initial Access tactic. Its four sub-techniques are T1566.001 Spearphishing Attachment, T1566.002 Spearphishing Link, T1566.003 Spearphishing via Service and T1566.004 Spearphishing Voice. | H4: According to ATT&CK, Phishing (T1566) belongs to the tactic **Initial Access** [4]. The context does not list four sub-techniques of T1566. It mentions the following sub-techniques: - T1566.004 - Spearphishing Voice [3] - T1566.001 - Social Media Accounts [1] - T1566.002 - Email Accounts [1] - T1566.003 - Cloud Accounts [1] However, only three of these are explicitly listed as sub-techniques of T1566 in the provided context. There is no mention of a fourth sub-technique. Therefore, based on the provided context, Phishing (T1566) belongs to the **Initial Access** tactic, and its sub-techniques are: - T1566.001 Social Media Accounts - T1566.002 Email Accounts - T1566.003 Cloud Accounts - T1566.004 Spearphishing Voice [1][3][4] | I4: NO | J4: PARTE | K4: 1/5 | L4: =COUNTIFS(Afirmaciones!$A$2:$A$401,$A4,Afirmaciones!$B$2:$B$401,$B4) -> 0 | M4: =COUNTIFS(Hechos!$A$2:$A$201,$A4) -> 5 | N4: =IF($B4="rag",SUMIFS(Hechos!$F$2:$F$201,Hechos!$A$2:$A$201,$A4),SUMIFS(Hechos!$G$2:$G$201,Hechos!$A$2:$A$201,$A4)) -> 0 | O4: =IF($M4=0,"-",$N4&"/"&$M4) -> 0/5 | P4: =COUNTIFS(Afirmaciones!$A$2:$A$401,$A4,Afirmaciones!$B$2:$B$401,$B4,Afirmaciones!$E$2:$E$401,"hecho",Afirmaciones!$F$2:$F$401,"INCORRECTA") -> 0 | Q4: =COUNTIFS(Afirmaciones!$A$2:$A$401,$A4,Afirmaciones!$B$2:$B$401,$B4,Afirmaciones!$E$2:$E$401,"abstencion",Afirmaciones!$F$2:$F$401,"INCORRECTA") -> 0 | R4: =COUNTIFS(Afirmaciones!$A$2:$A$401,$A4,Afirmaciones!$B$2:$B$401,$B4,Afirmaciones!$E$2:$E$401,"hecho",Afirmaciones!$F$2:$F$401,"FUERA_REF",Afirmaciones!$H$2:$H$401,"no_resp") -> 0 | S4: =COUNTIFS(Afirmaciones!$A$2:$A$401,$A4,Afirmaciones!$B$2:$B$401,$B4,Afirmaciones!$E$2:$E$401,"hecho",Afirmaciones!$F$2:$F$401,"FUERA_REF") -> 0 | T4: =COUNTIFS(Afirmaciones!$A$2:$A$401,$A4,Afirmaciones!$B$2:$B$401,$B4,Afirmaciones!$E$2:$E$401,"hecho",Afirmaciones!$I$2:$I$401,"SIN-RESPALDO") -> 0 | U4: =COUNTIFS(Afirmaciones!$A$2:$A$401,$A4,Afirmaciones!$B$2:$B$401,$B4,Afirmaciones!$E$2:$E$401,"hecho",Afirmaciones!$I$2:$I$401,"CITA-X") -> 0 | V4: =COUNTIFS(Afirmaciones!$A$2:$A$401,$A4,Afirmaciones!$B$2:$B$401,$B4,Afirmaciones!$E$2:$E$401,"hecho",Afirmaciones!$I$2:$I$401,"SIN-CITA") -> 0 | W4: =COUNTIFS(Afirmaciones!$A$2:$A$401,$A4,Afirmaciones!$B$2:$B$401,$B4,Afirmaciones!$E$2:$E$401,"hecho") -> 0 | X4: =COUNTIFS(Afirmaciones!$A$2:$A$401,$A4,Afirmaciones!$B$2:$B$401,$B4,Afirmaciones!$E$2:$E$401,"hecho",Afirmaciones!$I$2:$I$401,"SOSTENIDA") -> 0 | Y4: =IF($L4=0,"",IF($M4=0,IF($R4>0,0,2),IF(AND($N4=$M4,$P4+$Q4+$R4=0),2,IF($N4=0,0,1)))) | Z4: =IF($L4=0,"",IF($B4="llm","N/A",IF($W4=0,"N/A",IF($X4=$W4,2,IF($X4=0,0,1))))) | AA4: =IF($L4=0,"",IF(AND($P4+$Q4+$R4=0,$T4+$U4=0,$I4<>"SI"),"-",TRIM(IF($P4+$Q4+$R4>0,"CRITICA ","")&IF($T4+$U4>0,"RESPALDO ","")&IF($I4="SI","TRUNC","")))) | AB4: =IF($L4=0,"",IF(AND($R4=0,$AF4=0,$AG4=0,$P4+$Q4=0,$T4+$U4+$V4=0),"OK",TRIM(IF($R4>0,"E0 ","")&IF($AF4>0,"E1 ","")&IF(OR($AG4>0,AND($P4+$Q4>0,$AF4=0)),"E2 ","")&IF($T4+$U4+$V4>0,"E3 ","")))) | AC4: =IF($AB4="","",IF($AB4="OK","OK",LEFT($AB4,2))) | AD4: =IF(OR($L4=0,$B4="llm",$W4=0),"-",$X4&"/"&$W4) -> - | AE4: =IF(OR($L4=0,$B4<>"rag",$M4=0),"-",SUMIFS(Hechos!$H$2:$H$201,Hechos!$A$2:$A$201,$A4)&"/"&$M4) -> - | AF4: =IF($B4="rag",SUMPRODUCT((Hechos!$A$2:$A$201=$A4)*(Hechos!$F$2:$F$201=0)*((Hechos!$E$2:$E$201="NO")+(Hechos!$E$2:$E$201="ALT-P")+(Hechos!$E$2:$E$201=""))),0) -> 0 | AG4: =IF($B4="rag",SUMPRODUCT((Hechos!$A$2:$A$201=$A4)*(Hechos!$F$2:$F$201=0)*((Hechos!$E$2:$E$201="SI")+(Hechos!$E$2:$E$201="ALT"))),$M4-$N4) -> 0
A5: p02 | B5: llm | C5: EN | D5: completa | E5: According to ATT&CK, which tactic does Phishing (T1566) belong to and what are its four sub-techniques? | F5: Phishing belongs to the Initial Access tactic. Its four sub-techniques are T1566.001 Spearphishing Attachment, T1566.002 Spearphishing Link, T1566.003 Spearphishing via Service and T1566.004 Spearphishing Voice. | H5: Phishing (T1566) belongs to the **Tactic: Initial Access** in the MITRE ATT&CK framework. However, it's important to clarify: **T1566 is not a tactic** — it is a **technique**. The correct categorization is: - **Tactic**: Initial Access - **Technique**: T1566 – Phishing T1566 – Phishing is a technique under the **Initial Access** tactic. Regarding sub-techniques of T1566 (Phishing), MITRE ATT&CK does **not** define four distinct sub-techniques under T1566. Instead, T1566 is a single technique with various **sub-techniques** (or forms) that describe different types of phishing, such as: - T1566.001 – Spear Phishing Email - T1566.002 – Phishing Website - T1566.003 – Phishing SMS (Smishing) - T1566.004 – Phishing via Voice (Vishing) Thus, the four sub-techniques of T1566 are: - T1566.001 – Spear Phishing Email - T1566.002 – Phishing Website - T1566.003 – Phishing SMS (Smishing) - T1566.004 – Phishing via Voice (Vishing) ✅ Final Answer: According to ATT&CK, Phishing (T1566) belongs to the **Initial Access** tactic. Its four sub-techniques are: - T1566.001 – Spear Phishing Email - T1566.002 – Phishing Website - T1566.003 – Phishing SMS (Smishing) - T1566.004 – Phishing via Voice (Vishing) | I5: NO | L5: =COUNTIFS(Afirmaciones!$A$2:$A$401,$A5,Afirmaciones!$B$2:$B$401,$B5) -> 0 | M5: =COUNTIFS(Hechos!$A$2:$A$201,$A5) -> 5 | N5: =IF($B5="rag",SUMIFS(Hechos!$F$2:$F$201,Hechos!$A$2:$A$201,$A5),SUMIFS(Hechos!$G$2:$G$201,Hechos!$A$2:$A$201,$A5)) -> 0 | O5: =IF($M5=0,"-",$N5&"/"&$M5) -> 0/5 | P5: =COUNTIFS(Afirmaciones!$A$2:$A$401,$A5,Afirmaciones!$B$2:$B$401,$B5,Afirmaciones!$E$2:$E$401,"hecho",Afirmaciones!$F$2:$F$401,"INCORRECTA") -> 0 | Q5: =COUNTIFS(Afirmaciones!$A$2:$A$401,$A5,Afirmaciones!$B$2:$B$401,$B5,Afirmaciones!$E$2:$E$401,"abstencion",Afirmaciones!$F$2:$F$401,"INCORRECTA") -> 0 | R5: =COUNTIFS(Afirmaciones!$A$2:$A$401,$A5,Afirmaciones!$B$2:$B$401,$B5,Afirmaciones!$E$2:$E$401,"hecho",Afirmaciones!$F$2:$F$401,"FUERA_REF",Afirmaciones!$H$2:$H$401,"no_resp") -> 0 | S5: =COUNTIFS(Afirmaciones!$A$2:$A$401,$A5,Afirmaciones!$B$2:$B$401,$B5,Afirmaciones!$E$2:$E$401,"hecho",Afirmaciones!$F$2:$F$401,"FUERA_REF") -> 0 | T5: =COUNTIFS(Afirmaciones!$A$2:$A$401,$A5,Afirmaciones!$B$2:$B$401,$B5,Afirmaciones!$E$2:$E$401,"hecho",Afirmaciones!$I$2:$I$401,"SIN-RESPALDO") -> 0 | U5: =COUNTIFS(Afirmaciones!$A$2:$A$401,$A5,Afirmaciones!$B$2:$B$401,$B5,Afirmaciones!$E$2:$E$401,"hecho",Afirmaciones!$I$2:$I$401,"CITA-X") -> 0 | V5: =COUNTIFS(Afirmaciones!$A$2:$A$401,$A5,Afirmaciones!$B$2:$B$401,$B5,Afirmaciones!$E$2:$E$401,"hecho",Afirmaciones!$I$2:$I$401,"SIN-CITA") -> 0 | W5: =COUNTIFS(Afirmaciones!$A$2:$A$401,$A5,Afirmaciones!$B$2:$B$401,$B5,Afirmaciones!$E$2:$E$401,"hecho") -> 0 | X5: =COUNTIFS(Afirmaciones!$A$2:$A$401,$A5,Afirmaciones!$B$2:$B$401,$B5,Afirmaciones!$E$2:$E$401,"hecho",Afirmaciones!$I$2:$I$401,"SOSTENIDA") -> 0 | Y5: =IF($L5=0,"",IF($M5=0,IF($R5>0,0,2),IF(AND($N5=$M5,$P5+$Q5+$R5=0),2,IF($N5=0,0,1)))) | Z5: =IF($L5=0,"",IF($B5="llm","N/A",IF($W5=0,"N/A",IF($X5=$W5,2,IF($X5=0,0,1))))) | AA5: =IF($L5=0,"",IF(AND($P5+$Q5+$R5=0,$T5+$U5=0,$I5<>"SI"),"-",TRIM(IF($P5+$Q5+$R5>0,"CRITICA ","")&IF($T5+$U5>0,"RESPALDO ","")&IF($I5="SI","TRUNC","")))) | AB5: =IF($L5=0,"",IF(AND($R5=0,$AF5=0,$AG5=0,$P5+$Q5=0,$T5+$U5+$V5=0),"OK",TRIM(IF($R5>0,"E0 ","")&IF($AF5>0,"E1 ","")&IF(OR($AG5>0,AND($P5+$Q5>0,$AF5=0)),"E2 ","")&IF($T5+$U5+$V5>0,"E3 ","")))) | AC5: =IF($AB5="","",IF($AB5="OK","OK",LEFT($AB5,2))) | AD5: =IF(OR($L5=0,$B5="llm",$W5=0),"-",$X5&"/"&$W5) -> - | AE5: =IF(OR($L5=0,$B5<>"rag",$M5=0),"-",SUMIFS(Hechos!$H$2:$H$201,Hechos!$A$2:$A$201,$A5)&"/"&$M5) -> - | AF5: =IF($B5="rag",SUMPRODUCT((Hechos!$A$2:$A$201=$A5)*(Hechos!$F$2:$F$201=0)*((Hechos!$E$2:$E$201="NO")+(Hechos!$E$2:$E$201="ALT-P")+(Hechos!$E$2:$E$201=""))),0) -> 0 | AG5: =IF($B5="rag",SUMPRODUCT((Hechos!$A$2:$A$201=$A5)*(Hechos!$F$2:$F$201=0)*((Hechos!$E$2:$E$201="SI")+(Hechos!$E$2:$E$201="ALT"))),$M5-$N5) -> 5
A6: p03 | B6: rag | C6: ES | D6: completa | E6: ¿Qué es la táctica Persistencia (TA0003) en ATT&CK y qué busca conseguir el adversario con ella? | F6: Persistencia es la táctica en la que el adversario intenta mantener su punto de apoyo (foothold). Agrupa técnicas para conservar el acceso a los sistemas a pesar de reinicios, cambios de credenciales u otras interrupciones; incluye cualquier acceso, acción o cambio de configuración que le permita mantener ese acceso, como reemplazar o secuestrar código legítimo o añadir código de arranque. | H6: La táctica Persistencia (TA0003) en ATT&CK consiste en técnicas que los adversarios utilizan para mantener su acceso a los sistemas a pesar de reinicios, cambios de credenciales o interrupciones que podrían cortar su acceso [1]. Esta táctica busca que el adversario mantenga su presencia en los sistemas tras eventos que podrían eliminar su acceso, como reinicios o cambios de credenciales [1]. | I6: NO | J6: TODA | K6: 2/2 | L6: =COUNTIFS(Afirmaciones!$A$2:$A$401,$A6,Afirmaciones!$B$2:$B$401,$B6) -> 0 | M6: =COUNTIFS(Hechos!$A$2:$A$201,$A6) -> 2 | N6: =IF($B6="rag",SUMIFS(Hechos!$F$2:$F$201,Hechos!$A$2:$A$201,$A6),SUMIFS(Hechos!$G$2:$G$201,Hechos!$A$2:$A$201,$A6)) -> 0 | O6: =IF($M6=0,"-",$N6&"/"&$M6) -> 0/2 | P6: =COUNTIFS(Afirmaciones!$A$2:$A$401,$A6,Afirmaciones!$B$2:$B$401,$B6,Afirmaciones!$E$2:$E$401,"hecho",Afirmaciones!$F$2:$F$401,"INCORRECTA") -> 0 | Q6: =COUNTIFS(Afirmaciones!$A$2:$A$401,$A6,Afirmaciones!$B$2:$B$401,$B6,Afirmaciones!$E$2:$E$401,"abstencion",Afirmaciones!$F$2:$F$401,"INCORRECTA") -> 0 | R6: =COUNTIFS(Afirmaciones!$A$2:$A$401,$A6,Afirmaciones!$B$2:$B$401,$B6,Afirmaciones!$E$2:$E$401,"hecho",Afirmaciones!$F$2:$F$401,"FUERA_REF",Afirmaciones!$H$2:$H$401,"no_resp") -> 0 | S6: =COUNTIFS(Afirmaciones!$A$2:$A$401,$A6,Afirmaciones!$B$2:$B$401,$B6,Afirmaciones!$E$2:$E$401,"hecho",Afirmaciones!$F$2:$F$401,"FUERA_REF") -> 0 | T6: =COUNTIFS(Afirmaciones!$A$2:$A$401,$A6,Afirmaciones!$B$2:$B$401,$B6,Afirmaciones!$E$2:$E$401,"hecho",Afirmaciones!$I$2:$I$401,"SIN-RESPALDO") -> 0 | U6: =COUNTIFS(Afirmaciones!$A$2:$A$401,$A6,Afirmaciones!$B$2:$B$401,$B6,Afirmaciones!$E$2:$E$401,"hecho",Afirmaciones!$I$2:$I$401,"CITA-X") -> 0 | V6: =COUNTIFS(Afirmaciones!$A$2:$A$401,$A6,Afirmaciones!$B$2:$B$401,$B6,Afirmaciones!$E$2:$E$401,"hecho",Afirmaciones!$I$2:$I$401,"SIN-CITA") -> 0 | W6: =COUNTIFS(Afirmaciones!$A$2:$A$401,$A6,Afirmaciones!$B$2:$B$401,$B6,Afirmaciones!$E$2:$E$401,"hecho") -> 0 | X6: =COUNTIFS(Afirmaciones!$A$2:$A$401,$A6,Afirmaciones!$B$2:$B$401,$B6,Afirmaciones!$E$2:$E$401,"hecho",Afirmaciones!$I$2:$I$401,"SOSTENIDA") -> 0 | Y6: =IF($L6=0,"",IF($M6=0,IF($R6>0,0,2),IF(AND($N6=$M6,$P6+$Q6+$R6=0),2,IF($N6=0,0,1)))) | Z6: =IF($L6=0,"",IF($B6="llm","N/A",IF($W6=0,"N/A",IF($X6=$W6,2,IF($X6=0,0,1))))) | AA6: =IF($L6=0,"",IF(AND($P6+$Q6+$R6=0,$T6+$U6=0,$I6<>"SI"),"-",TRIM(IF($P6+$Q6+$R6>0,"CRITICA ","")&IF($T6+$U6>0,"RESPALDO ","")&IF($I6="SI","TRUNC","")))) | AB6: =IF($L6=0,"",IF(AND($R6=0,$AF6=0,$AG6=0,$P6+$Q6=0,$T6+$U6+$V6=0),"OK",TRIM(IF($R6>0,"E0 ","")&IF($AF6>0,"E1 ","")&IF(OR($AG6>0,AND($P6+$Q6>0,$AF6=0)),"E2 ","")&IF($T6+$U6+$V6>0,"E3 ","")))) | AC6: =IF($AB6="","",IF($AB6="OK","OK",LEFT($AB6,2))) | AD6: =IF(OR($L6=0,$B6="llm",$W6=0),"-",$X6&"/"&$W6) -> - | AE6: =IF(OR($L6=0,$B6<>"rag",$M6=0),"-",SUMIFS(Hechos!$H$2:$H$201,Hechos!$A$2:$A$201,$A6)&"/"&$M6) -> - | AF6: =IF($B6="rag",SUMPRODUCT((Hechos!$A$2:$A$201=$A6)*(Hechos!$F$2:$F$201=0)*((Hechos!$E$2:$E$201="NO")+(Hechos!$E$2:$E$201="ALT-P")+(Hechos!$E$2:$E$201=""))),0) -> 0 | AG6: =IF($B6="rag",SUMPRODUCT((Hechos!$A$2:$A$201=$A6)*(Hechos!$F$2:$F$201=0)*((Hechos!$E$2:$E$201="SI")+(Hechos!$E$2:$E$201="ALT"))),$M6-$N6) -> 0
A7: p03 | B7: llm | C7: ES | D7: completa | E7: ¿Qué es la táctica Persistencia (TA0003) en ATT&CK y qué busca conseguir el adversario con ella? | F7: Persistencia es la táctica en la que el adversario intenta mantener su punto de apoyo (foothold). Agrupa técnicas para conservar el acceso a los sistemas a pesar de reinicios, cambios de credenciales u otras interrupciones; incluye cualquier acceso, acción o cambio de configuración que le permita mantener ese acceso, como reemplazar o secuestrar código legítimo o añadir código de arranque. | H7: La táctica Persistencia (TA0003) en el marco MITRE ATT&CK se refiere a la capacidad de un atacante para mantener acceso a un sistema o red tras la inicialización de una amenaza. Este objetivo permite que el atacante se mantenga activo en el entorno durante períodos prolongados, incluso después de que se hayan aplicado medidas de seguridad o se hayan detectado actividades inusuales. El adversario busca conseguir que su acceso a la infraestructura sea **persistente**, es decir, que no se pierda al reiniciar el sistema o al aplicar controles de seguridad. Esto permite que el atacante realice actividades de recolección de datos, ejecución de comandos, propagación a otros sistemas o monitoreo continuo sin que se detecte inmediatamente. Algunos ejemplos de técnicas asociadas a esta táctica incluyen: - T1059.001 (Comandos y scripts maliciosos) - T1059.002 (Ejecución de scripts) - T1059.003 (Ejecución de comandos) - T1059.004 (Ejecución de comandos a través de servicios) - T1059.005 (Ejecución de comandos a través de servicios de red) En resumen, la táctica Persistencia (TA0003) busca **mantener un acceso continuo y sin interrupción** al sistema objetivo, lo que facilita la ejecución de ataques más complejos y prolongados. | I7: NO | L7: =COUNTIFS(Afirmaciones!$A$2:$A$401,$A7,Afirmaciones!$B$2:$B$401,$B7) -> 0 | M7: =COUNTIFS(Hechos!$A$2:$A$201,$A7) -> 2 | N7: =IF($B7="rag",SUMIFS(Hechos!$F$2:$F$201,Hechos!$A$2:$A$201,$A7),SUMIFS(Hechos!$G$2:$G$201,Hechos!$A$2:$A$201,$A7)) -> 0 | O7: =IF($M7=0,"-",$N7&"/"&$M7) -> 0/2 | P7: =COUNTIFS(Afirmaciones!$A$2:$A$401,$A7,Afirmaciones!$B$2:$B$401,$B7,Afirmaciones!$E$2:$E$401,"hecho",Afirmaciones!$F$2:$F$401,"INCORRECTA") -> 0 | Q7: =COUNTIFS(Afirmaciones!$A$2:$A$401,$A7,Afirmaciones!$B$2:$B$401,$B7,Afirmaciones!$E$2:$E$401,"abstencion",Afirmaciones!$F$2:$F$401,"INCORRECTA") -> 0 | R7: =COUNTIFS(Afirmaciones!$A$2:$A$401,$A7,Afirmaciones!$B$2:$B$401,$B7,Afirmaciones!$E$2:$E$401,"hecho",Afirmaciones!$F$2:$F$401,"FUERA_REF",Afirmaciones!$H$2:$H$401,"no_resp") -> 0 | S7: =COUNTIFS(Afirmaciones!$A$2:$A$401,$A7,Afirmaciones!$B$2:$B$401,$B7,Afirmaciones!$E$2:$E$401,"hecho",Afirmaciones!$F$2:$F$401,"FUERA_REF") -> 0 | T7: =COUNTIFS(Afirmaciones!$A$2:$A$401,$A7,Afirmaciones!$B$2:$B$401,$B7,Afirmaciones!$E$2:$E$401,"hecho",Afirmaciones!$I$2:$I$401,"SIN-RESPALDO") -> 0 | U7: =COUNTIFS(Afirmaciones!$A$2:$A$401,$A7,Afirmaciones!$B$2:$B$401,$B7,Afirmaciones!$E$2:$E$401,"hecho",Afirmaciones!$I$2:$I$401,"CITA-X") -> 0 | V7: =COUNTIFS(Afirmaciones!$A$2:$A$401,$A7,Afirmaciones!$B$2:$B$401,$B7,Afirmaciones!$E$2:$E$401,"hecho",Afirmaciones!$I$2:$I$401,"SIN-CITA") -> 0 | W7: =COUNTIFS(Afirmaciones!$A$2:$A$401,$A7,Afirmaciones!$B$2:$B$401,$B7,Afirmaciones!$E$2:$E$401,"hecho") -> 0 | X7: =COUNTIFS(Afirmaciones!$A$2:$A$401,$A7,Afirmaciones!$B$2:$B$401,$B7,Afirmaciones!$E$2:$E$401,"hecho",Afirmaciones!$I$2:$I$401,"SOSTENIDA") -> 0 | Y7: =IF($L7=0,"",IF($M7=0,IF($R7>0,0,2),IF(AND($N7=$M7,$P7+$Q7+$R7=0),2,IF($N7=0,0,1)))) | Z7: =IF($L7=0,"",IF($B7="llm","N/A",IF($W7=0,"N/A",IF($X7=$W7,2,IF($X7=0,0,1))))) | AA7: =IF($L7=0,"",IF(AND($P7+$Q7+$R7=0,$T7+$U7=0,$I7<>"SI"),"-",TRIM(IF($P7+$Q7+$R7>0,"CRITICA ","")&IF($T7+$U7>0,"RESPALDO ","")&IF($I7="SI","TRUNC","")))) | AB7: =IF($L7=0,"",IF(AND($R7=0,$AF7=0,$AG7=0,$P7+$Q7=0,$T7+$U7+$V7=0),"OK",TRIM(IF($R7>0,"E0 ","")&IF($AF7>0,"E1 ","")&IF(OR($AG7>0,AND($P7+$Q7>0,$AF7=0)),"E2 ","")&IF($T7+$U7+$V7>0,"E3 ","")))) | AC7: =IF($AB7="","",IF($AB7="OK","OK",LEFT($AB7,2))) | AD7: =IF(OR($L7=0,$B7="llm",$W7=0),"-",$X7&"/"&$W7) -> - | AE7: =IF(OR($L7=0,$B7<>"rag",$M7=0),"-",SUMIFS(Hechos!$H$2:$H$201,Hechos!$A$2:$A$201,$A7)&"/"&$M7) -> - | AF7: =IF($B7="rag",SUMPRODUCT((Hechos!$A$2:$A$201=$A7)*(Hechos!$F$2:$F$201=0)*((Hechos!$E$2:$E$201="NO")+(Hechos!$E$2:$E$201="ALT-P")+(Hechos!$E$2:$E$201=""))),0) -> 0 | AG7: =IF($B7="rag",SUMPRODUCT((Hechos!$A$2:$A$201=$A7)*(Hechos!$F$2:$F$201=0)*((Hechos!$E$2:$E$201="SI")+(Hechos!$E$2:$E$201="ALT"))),$M7-$N7) -> 2
A8: p04 | B8: rag | C8: ES | D8: parcial | E8: Según ATT&CK, ¿qué es Cobalt Strike (S0154) y de qué otras herramientas conocidas aprovecha capacidades? ¿Cuánto cuesta su licencia anual? | F8: Cobalt Strike es una herramienta comercial de acceso remoto con todas las funciones, que se presenta como 'software de simulación de adversarios' para ejecutar ataques dirigidos y emular las acciones post-explotación de actores avanzados; sus capacidades interactivas cubren toda la gama de tácticas ATT&CK en un único sistema integrado. Además de sus propias capacidades, aprovecha las de otras herramientas conocidas como Metasploit y Mimikatz (S0002). | G8: El precio de la licencia no está en el corpus (ATT&CK no registra precios; la única aparición de 'price' en el corpus es en el software CoinTicker, sin relación). | H8: Según ATT&CK, Cobalt Strike (S0154) es un software de tipo malware, perteneciente al dominio de ataque empresarial, que se describe como "una herramienta de acceso remoto comercial, completa, diseñada para ejecutar ataques dirigidos y emular las acciones de post-explotación de actores de amenazas avanzadas". [1] Cobalt Strike aprovecha las capacidades de otras herramientas conocidas, como Metasploit y Mimikatz. [1] No se proporciona información en los contextos sobre el costo anual de la licencia de Cobalt Strike. [1][2][3][4][5] Por lo tanto, no se puede determinar cuánto cuesta su licencia anual basándose en los datos proporcionados. | I8: NO | J8: TODA | K8: 2/2 | L8: =COUNTIFS(Afirmaciones!$A$2:$A$401,$A8,Afirmaciones!$B$2:$B$401,$B8) -> 0 | M8: =COUNTIFS(Hechos!$A$2:$A$201,$A8) -> 2 | N8: =IF($B8="rag",SUMIFS(Hechos!$F$2:$F$201,Hechos!$A$2:$A$201,$A8),SUMIFS(Hechos!$G$2:$G$201,Hechos!$A$2:$A$201,$A8)) -> 0 | O8: =IF($M8=0,"-",$N8&"/"&$M8) -> 0/2 | P8: =COUNTIFS(Afirmaciones!$A$2:$A$401,$A8,Afirmaciones!$B$2:$B$401,$B8,Afirmaciones!$E$2:$E$401,"hecho",Afirmaciones!$F$2:$F$401,"INCORRECTA") -> 0 | Q8: =COUNTIFS(Afirmaciones!$A$2:$A$401,$A8,Afirmaciones!$B$2:$B$401,$B8,Afirmaciones!$E$2:$E$401,"abstencion",Afirmaciones!$F$2:$F$401,"INCORRECTA") -> 0 | R8: =COUNTIFS(Afirmaciones!$A$2:$A$401,$A8,Afirmaciones!$B$2:$B$401,$B8,Afirmaciones!$E$2:$E$401,"hecho",Afirmaciones!$F$2:$F$401,"FUERA_REF",Afirmaciones!$H$2:$H$401,"no_resp") -> 0 | S8: =COUNTIFS(Afirmaciones!$A$2:$A$401,$A8,Afirmaciones!$B$2:$B$401,$B8,Afirmaciones!$E$2:$E$401,"hecho",Afirmaciones!$F$2:$F$401,"FUERA_REF") -> 0 | T8: =COUNTIFS(Afirmaciones!$A$2:$A$401,$A8,Afirmaciones!$B$2:$B$401,$B8,Afirmaciones!$E$2:$E$401,"hecho",Afirmaciones!$I$2:$I$401,"SIN-RESPALDO") -> 0 | U8: =COUNTIFS(Afirmaciones!$A$2:$A$401,$A8,Afirmaciones!$B$2:$B$401,$B8,Afirmaciones!$E$2:$E$401,"hecho",Afirmaciones!$I$2:$I$401,"CITA-X") -> 0 | V8: =COUNTIFS(Afirmaciones!$A$2:$A$401,$A8,Afirmaciones!$B$2:$B$401,$B8,Afirmaciones!$E$2:$E$401,"hecho",Afirmaciones!$I$2:$I$401,"SIN-CITA") -> 0 | W8: =COUNTIFS(Afirmaciones!$A$2:$A$401,$A8,Afirmaciones!$B$2:$B$401,$B8,Afirmaciones!$E$2:$E$401,"hecho") -> 0 | X8: =COUNTIFS(Afirmaciones!$A$2:$A$401,$A8,Afirmaciones!$B$2:$B$401,$B8,Afirmaciones!$E$2:$E$401,"hecho",Afirmaciones!$I$2:$I$401,"SOSTENIDA") -> 0 | Y8: =IF($L8=0,"",IF($M8=0,IF($R8>0,0,2),IF(AND($N8=$M8,$P8+$Q8+$R8=0),2,IF($N8=0,0,1)))) | Z8: =IF($L8=0,"",IF($B8="llm","N/A",IF($W8=0,"N/A",IF($X8=$W8,2,IF($X8=0,0,1))))) | AA8: =IF($L8=0,"",IF(AND($P8+$Q8+$R8=0,$T8+$U8=0,$I8<>"SI"),"-",TRIM(IF($P8+$Q8+$R8>0,"CRITICA ","")&IF($T8+$U8>0,"RESPALDO ","")&IF($I8="SI","TRUNC","")))) | AB8: =IF($L8=0,"",IF(AND($R8=0,$AF8=0,$AG8=0,$P8+$Q8=0,$T8+$U8+$V8=0),"OK",TRIM(IF($R8>0,"E0 ","")&IF($AF8>0,"E1 ","")&IF(OR($AG8>0,AND($P8+$Q8>0,$AF8=0)),"E2 ","")&IF($T8+$U8+$V8>0,"E3 ","")))) | AC8: =IF($AB8="","",IF($AB8="OK","OK",LEFT($AB8,2))) | AD8: =IF(OR($L8=0,$B8="llm",$W8=0),"-",$X8&"/"&$W8) -> - | AE8: =IF(OR($L8=0,$B8<>"rag",$M8=0),"-",SUMIFS(Hechos!$H$2:$H$201,Hechos!$A$2:$A$201,$A8)&"/"&$M8) -> - | AF8: =IF($B8="rag",SUMPRODUCT((Hechos!$A$2:$A$201=$A8)*(Hechos!$F$2:$F$201=0)*((Hechos!$E$2:$E$201="NO")+(Hechos!$E$2:$E$201="ALT-P")+(Hechos!$E$2:$E$201=""))),0) -> 0 | AG8: =IF($B8="rag",SUMPRODUCT((Hechos!$A$2:$A$201=$A8)*(Hechos!$F$2:$F$201=0)*((Hechos!$E$2:$E$201="SI")+(Hechos!$E$2:$E$201="ALT"))),$M8-$N8) -> 0
A9: p04 | B9: llm | C9: ES | D9: parcial | E9: Según ATT&CK, ¿qué es Cobalt Strike (S0154) y de qué otras herramientas conocidas aprovecha capacidades? ¿Cuánto cuesta su licencia anual? | F9: Cobalt Strike es una herramienta comercial de acceso remoto con todas las funciones, que se presenta como 'software de simulación de adversarios' para ejecutar ataques dirigidos y emular las acciones post-explotación de actores avanzados; sus capacidades interactivas cubren toda la gama de tácticas ATT&CK en un único sistema integrado. Además de sus propias capacidades, aprovecha las de otras herramientas conocidas como Metasploit y Mimikatz (S0002). | G9: El precio de la licencia no está en el corpus (ATT&CK no registra precios; la única aparición de 'price' en el corpus es en el software CoinTicker, sin relación). | H9: Cobalt Strike (S0154) es una herramienta de red de seguridad y de ataque que permite a los investigadores y profesionales de ciberseguridad realizar pruebas de penetración y análisis de vulnerabilidades en entornos de red. Según el MITRE ATT&CK, S0154 se clasifica como una herramienta de "iniciación de sesión" (initial access) y se utiliza principalmente para simular ataques de red, como la ejecución remota de comandos en sistemas. Cobalt Strike aprovecha capacidades de otras herramientas conocidas, como: - **Metasploit**: para la ejecución de payloads y la gestión de sesiones. - **PowerShell**: para la ejecución de comandos en sistemas Windows. - **Meterpreter**: un módulo de Metasploit que permite la ejecución remota de comandos y la gestión de sesiones en sistemas operativos. Sin embargo, es importante aclarar que **Cobalt Strike no es una herramienta de ataque comercial que se venda con una licencia anual**. Es una herramienta de investigación y pruebas de penetración que se ofrece como software de uso académico y profesional, y **no tiene un costo oficial de licencia anual** como producto comercializado en el mercado. En su sitio oficial, Cobalt Strike está disponible para uso en entornos de pruebas y educación, y **no se cobra una licencia anual**. Su uso está regulado por las políticas de uso de la herramienta, y se recomienda su uso solo en entornos autorizados y bajo supervisión. 👉 **Respuesta final**: Cobalt Strike (S0150) es una herramienta de pruebas de penetración que simula ataques de red y aprovecha capacidades de herramientas como Metasploit y PowerShell. **No tiene una licencia anual y no se cobra un costo oficial** para su uso en entornos educativos o de investigación. | I9: NO | L9: =COUNTIFS(Afirmaciones!$A$2:$A$401,$A9,Afirmaciones!$B$2:$B$401,$B9) -> 0 | M9: =COUNTIFS(Hechos!$A$2:$A$201,$A9) -> 2 | N9: =IF($B9="rag",SUMIFS(Hechos!$F$2:$F$201,Hechos!$A$2:$A$201,$A9),SUMIFS(Hechos!$G$2:$G$201,Hechos!$A$2:$A$201,$A9)) -> 0 | O9: =IF($M9=0,"-",$N9&"/"&$M9) -> 0/2 | P9: =COUNTIFS(Afirmaciones!$A$2:$A$401,$A9,Afirmaciones!$B$2:$B$401,$B9,Afirmaciones!$E$2:$E$401,"hecho",Afirmaciones!$F$2:$F$401,"INCORRECTA") -> 0 | Q9: =COUNTIFS(Afirmaciones!$A$2:$A$401,$A9,Afirmaciones!$B$2:$B$401,$B9,Afirmaciones!$E$2:$E$401,"abstencion",Afirmaciones!$F$2:$F$401,"INCORRECTA") -> 0 | R9: =COUNTIFS(Afirmaciones!$A$2:$A$401,$A9,Afirmaciones!$B$2:$B$401,$B9,Afirmaciones!$E$2:$E$401,"hecho",Afirmaciones!$F$2:$F$401,"FUERA_REF",Afirmaciones!$H$2:$H$401,"no_resp") -> 0 | S9: =COUNTIFS(Afirmaciones!$A$2:$A$401,$A9,Afirmaciones!$B$2:$B$401,$B9,Afirmaciones!$E$2:$E$401,"hecho",Afirmaciones!$F$2:$F$401,"FUERA_REF") -> 0 | T9: =COUNTIFS(Afirmaciones!$A$2:$A$401,$A9,Afirmaciones!$B$2:$B$401,$B9,Afirmaciones!$E$2:$E$401,"hecho",Afirmaciones!$I$2:$I$401,"SIN-RESPALDO") -> 0 | U9: =COUNTIFS(Afirmaciones!$A$2:$A$401,$A9,Afirmaciones!$B$2:$B$401,$B9,Afirmaciones!$E$2:$E$401,"hecho",Afirmaciones!$I$2:$I$401,"CITA-X") -> 0 | V9: =COUNTIFS(Afirmaciones!$A$2:$A$401,$A9,Afirmaciones!$B$2:$B$401,$B9,Afirmaciones!$E$2:$E$401,"hecho",Afirmaciones!$I$2:$I$401,"SIN-CITA") -> 0 | W9: =COUNTIFS(Afirmaciones!$A$2:$A$401,$A9,Afirmaciones!$B$2:$B$401,$B9,Afirmaciones!$E$2:$E$401,"hecho") -> 0 | X9: =COUNTIFS(Afirmaciones!$A$2:$A$401,$A9,Afirmaciones!$B$2:$B$401,$B9,Afirmaciones!$E$2:$E$401,"hecho",Afirmaciones!$I$2:$I$401,"SOSTENIDA") -> 0 | Y9: =IF($L9=0,"",IF($M9=0,IF($R9>0,0,2),IF(AND($N9=$M9,$P9+$Q9+$R9=0),2,IF($N9=0,0,1)))) | Z9: =IF($L9=0,"",IF($B9="llm","N/A",IF($W9=0,"N/A",IF($X9=$W9,2,IF($X9=0,0,1))))) | AA9: =IF($L9=0,"",IF(AND($P9+$Q9+$R9=0,$T9+$U9=0,$I9<>"SI"),"-",TRIM(IF($P9+$Q9+$R9>0,"CRITICA ","")&IF($T9+$U9>0,"RESPALDO ","")&IF($I9="SI","TRUNC","")))) | AB9: =IF($L9=0,"",IF(AND($R9=0,$AF9=0,$AG9=0,$P9+$Q9=0,$T9+$U9+$V9=0),"OK",TRIM(IF($R9>0,"E0 ","")&IF($AF9>0,"E1 ","")&IF(OR($AG9>0,AND($P9+$Q9>0,$AF9=0)),"E2 ","")&IF($T9+$U9+$V9>0,"E3 ","")))) | AC9: =IF($AB9="","",IF($AB9="OK","OK",LEFT($AB9,2))) | AD9: =IF(OR($L9=0,$B9="llm",$W9=0),"-",$X9&"/"&$W9) -> - | AE9: =IF(OR($L9=0,$B9<>"rag",$M9=0),"-",SUMIFS(Hechos!$H$2:$H$201,Hechos!$A$2:$A$201,$A9)&"/"&$M9) -> - | AF9: =IF($B9="rag",SUMPRODUCT((Hechos!$A$2:$A$201=$A9)*(Hechos!$F$2:$F$201=0)*((Hechos!$E$2:$E$201="NO")+(Hechos!$E$2:$E$201="ALT-P")+(Hechos!$E$2:$E$201=""))),0) -> 0 | AG9: =IF($B9="rag",SUMPRODUCT((Hechos!$A$2:$A$201=$A9)*(Hechos!$F$2:$F$201=0)*((Hechos!$E$2:$E$201="SI")+(Hechos!$E$2:$E$201="ALT"))),$M9-$N9) -> 2
A10: p05 | B10: rag | C10: ES | D10: completa | E10: Según ATT&CK, ¿APT29 (G0016) utiliza Mimikatz? Y en caso afirmativo, ¿qué técnicas relacionadas con tickets Kerberos implementa esa herramienta? | F10: Sí: S0002 Mimikatz aparece en la lista de software usado por APT29 (y G0016 APT29 aparece en la lista 'Used by' de Mimikatz). Entre las técnicas de Mimikatz relacionadas con tickets Kerberos están T1550.003 Pass the Ticket, T1558.001 Golden Ticket y T1558.002 Silver Ticket. | H10: Sí, según ATT&CK, APT29 (G0016) utiliza Mimikatz. En el contexto se indica que: - G0016 APT29 (grupo) ha utilizado ataques de Kerberos para el movimiento lateral [1]. - S0002 Mimikatz (software) tiene el módulo <code>KERBEROS::PTT</code> que implementa los tres pasos necesarios para extraer la contraseña del cuenta krbtgt y crear o usar tickets de Kerberos [1]. Por lo tanto, Mimikatz implementa la técnica **T1550.003 - Pass the Ticket**, que es una técnica relacionada con tickets de Kerberos. **Respuesta final:** Sí, APT29 (G0016) utiliza Mimikatz, y la técnica relacionada con tickets de Kerberos que implementa esa herramienta es **T1550.003 - Pass the Ticket** [1]. | I10: NO | J10: PARTE | K10: 2/4 | L10: =COUNTIFS(Afirmaciones!$A$2:$A$401,$A10,Afirmaciones!$B$2:$B$401,$B10) -> 3 | M10: =COUNTIFS(Hechos!$A$2:$A$201,$A10) -> 4 | N10: =IF($B10="rag",SUMIFS(Hechos!$F$2:$F$201,Hechos!$A$2:$A$201,$A10),SUMIFS(Hechos!$G$2:$G$201,Hechos!$A$2:$A$201,$A10)) -> 2 | O10: =IF($M10=0,"-",$N10&"/"&$M10) -> 2/4 | P10: =COUNTIFS(Afirmaciones!$A$2:$A$401,$A10,Afirmaciones!$B$2:$B$401,$B10,Afirmaciones!$E$2:$E$401,"hecho",Afirmaciones!$F$2:$F$401,"INCORRECTA") -> 0 | Q10: =COUNTIFS(Afirmaciones!$A$2:$A$401,$A10,Afirmaciones!$B$2:$B$401,$B10,Afirmaciones!$E$2:$E$401,"abstencion",Afirmaciones!$F$2:$F$401,"INCORRECTA") -> 0 | R10: =COUNTIFS(Afirmaciones!$A$2:$A$401,$A10,Afirmaciones!$B$2:$B$401,$B10,Afirmaciones!$E$2:$E$401,"hecho",Afirmaciones!$F$2:$F$401,"FUERA_REF",Afirmaciones!$H$2:$H$401,"no_resp") -> 0 | S10: =COUNTIFS(Afirmaciones!$A$2:$A$401,$A10,Afirmaciones!$B$2:$B$401,$B10,Afirmaciones!$E$2:$E$401,"hecho",Afirmaciones!$F$2:$F$401,"FUERA_REF") -> 1 | T10: =COUNTIFS(Afirmaciones!$A$2:$A$401,$A10,Afirmaciones!$B$2:$B$401,$B10,Afirmaciones!$E$2:$E$401,"hecho",Afirmaciones!$I$2:$I$401,"SIN-RESPALDO") -> 1 | U10: =COUNTIFS(Afirmaciones!$A$2:$A$401,$A10,Afirmaciones!$B$2:$B$401,$B10,Afirmaciones!$E$2:$E$401,"hecho",Afirmaciones!$I$2:$I$401,"CITA-X") -> 0 | V10: =COUNTIFS(Afirmaciones!$A$2:$A$401,$A10,Afirmaciones!$B$2:$B$401,$B10,Afirmaciones!$E$2:$E$401,"hecho",Afirmaciones!$I$2:$I$401,"SIN-CITA") -> 0 | W10: =COUNTIFS(Afirmaciones!$A$2:$A$401,$A10,Afirmaciones!$B$2:$B$401,$B10,Afirmaciones!$E$2:$E$401,"hecho") -> 3 | X10: =COUNTIFS(Afirmaciones!$A$2:$A$401,$A10,Afirmaciones!$B$2:$B$401,$B10,Afirmaciones!$E$2:$E$401,"hecho",Afirmaciones!$I$2:$I$401,"SOSTENIDA") -> 2 | Y10: =IF($L10=0,"",IF($M10=0,IF($R10>0,0,2),IF(AND($N10=$M10,$P10+$Q10+$R10=0),2,IF($N10=0,0,1)))) -> 1 | Z10: =IF($L10=0,"",IF($B10="llm","N/A",IF($W10=0,"N/A",IF($X10=$W10,2,IF($X10=0,0,1))))) -> 1 | AA10: =IF($L10=0,"",IF(AND($P10+$Q10+$R10=0,$T10+$U10=0,$I10<>"SI"),"-",TRIM(IF($P10+$Q10+$R10>0,"CRITICA ","")&IF($T10+$U10>0,"RESPALDO ","")&IF($I10="SI","TRUNC","")))) -> RESPALDO | AB10: =IF($L10=0,"",IF(AND($R10=0,$AF10=0,$AG10=0,$P10+$Q10=0,$T10+$U10+$V10=0),"OK",TRIM(IF($R10>0,"E0 ","")&IF($AF10>0,"E1 ","")&IF(OR($AG10>0,AND($P10+$Q10>0,$AF10=0)),"E2 ","")&IF($T10+$U10+$V10>0,"E3 ","")))) -> E1 E2 E3 | AC10: =IF($AB10="","",IF($AB10="OK","OK",LEFT($AB10,2))) -> E1 | AD10: =IF(OR($L10=0,$B10="llm",$W10=0),"-",$X10&"/"&$W10) -> 2/3 | AE10: =IF(OR($L10=0,$B10<>"rag",$M10=0),"-",SUMIFS(Hechos!$H$2:$H$201,Hechos!$A$2:$A$201,$A10)&"/"&$M10) -> 1/4 | AF10: =IF($B10="rag",SUMPRODUCT((Hechos!$A$2:$A$201=$A10)*(Hechos!$F$2:$F$201=0)*((Hechos!$E$2:$E$201="NO")+(Hechos!$E$2:$E$201="ALT-P")+(Hechos!$E$2:$E$201=""))),0) -> 1 | AG10: =IF($B10="rag",SUMPRODUCT((Hechos!$A$2:$A$201=$A10)*(Hechos!$F$2:$F$201=0)*((Hechos!$E$2:$E$201="SI")+(Hechos!$E$2:$E$201="ALT"))),$M10-$N10) -> 1 | AI10: 1 | 1 | E1 E2 E3
A11: p05 | B11: llm | C11: ES | D11: completa | E11: Según ATT&CK, ¿APT29 (G0016) utiliza Mimikatz? Y en caso afirmativo, ¿qué técnicas relacionadas con tickets Kerberos implementa esa herramienta? | F11: Sí: S0002 Mimikatz aparece en la lista de software usado por APT29 (y G0016 APT29 aparece en la lista 'Used by' de Mimikatz). Entre las técnicas de Mimikatz relacionadas con tickets Kerberos están T1550.003 Pass the Ticket, T1558.001 Golden Ticket y T1558.002 Silver Ticket. | H11: No, según el marco MITRE ATT&CK, el grupo APT29 (identificado como G0016) no se ha documentado como usuario directo de Mimikatz. Aunque APT29 ha sido asociado con técnicas de acceso a sistemas mediante el uso de tickets Kerberos (como T1547.001 - "Exploitation of Kerberos"), estas acciones se realizan mediante herramientas o métodos específicos de ataque, no necesariamente mediante Mimikatz. Además, Mimikatz es una herramienta de análisis de seguridad que permite la extracción de credenciales almacenadas en memoria (como los tickets Kerberos), y aunque puede ser utilizada por atacantes para obtener acceso a sistemas, su uso no está directamente vinculado a APT29 en fuentes oficiales del MITRE ATT&CK. En cuanto a técnicas relacionadas con tickets Kerberos que podría implementar APT29: - **T1547.001 - Exploitation of Kerberos**: Este es el principal sub-técnico relacionado con el uso de tickets Kerberos para obtener acceso a sistemas. APT29 ha sido asociado con este comportamiento, especialmente en ataques que aprovechan vulnerabilidades en el protocolo Kerberos (por ejemplo, en el uso de tickets de tiempo de vida o en la reutilización de tickets). Por lo tanto: ✅ APT29 (G0016) **no utiliza directamente Mimikatz**. ✅ APT29 **sí implementa técnicas relacionadas con el uso de tickets Kerberos**, principalmente **T1547.001**. **Respuesta final:** No, APT29 (G0016) no utiliza Mimikatz. Sin embargo, sí implementa la técnica T1547.001 - Exploitation of Kerberos. | I11: NO | L11: =COUNTIFS(Afirmaciones!$A$2:$A$401,$A11,Afirmaciones!$B$2:$B$401,$B11) -> 3 | M11: =COUNTIFS(Hechos!$A$2:$A$201,$A11) -> 4 | N11: =IF($B11="rag",SUMIFS(Hechos!$F$2:$F$201,Hechos!$A$2:$A$201,$A11),SUMIFS(Hechos!$G$2:$G$201,Hechos!$A$2:$A$201,$A11)) -> 0 | O11: =IF($M11=0,"-",$N11&"/"&$M11) -> 0/4 | P11: =COUNTIFS(Afirmaciones!$A$2:$A$401,$A11,Afirmaciones!$B$2:$B$401,$B11,Afirmaciones!$E$2:$E$401,"hecho",Afirmaciones!$F$2:$F$401,"INCORRECTA") -> 2 | Q11: =COUNTIFS(Afirmaciones!$A$2:$A$401,$A11,Afirmaciones!$B$2:$B$401,$B11,Afirmaciones!$E$2:$E$401,"abstencion",Afirmaciones!$F$2:$F$401,"INCORRECTA") -> 0 | R11: =COUNTIFS(Afirmaciones!$A$2:$A$401,$A11,Afirmaciones!$B$2:$B$401,$B11,Afirmaciones!$E$2:$E$401,"hecho",Afirmaciones!$F$2:$F$401,"FUERA_REF",Afirmaciones!$H$2:$H$401,"no_resp") -> 0 | S11: =COUNTIFS(Afirmaciones!$A$2:$A$401,$A11,Afirmaciones!$B$2:$B$401,$B11,Afirmaciones!$E$2:$E$401,"hecho",Afirmaciones!$F$2:$F$401,"FUERA_REF") -> 1 | T11: =COUNTIFS(Afirmaciones!$A$2:$A$401,$A11,Afirmaciones!$B$2:$B$401,$B11,Afirmaciones!$E$2:$E$401,"hecho",Afirmaciones!$I$2:$I$401,"SIN-RESPALDO") -> 0 | U11: =COUNTIFS(Afirmaciones!$A$2:$A$401,$A11,Afirmaciones!$B$2:$B$401,$B11,Afirmaciones!$E$2:$E$401,"hecho",Afirmaciones!$I$2:$I$401,"CITA-X") -> 0 | V11: =COUNTIFS(Afirmaciones!$A$2:$A$401,$A11,Afirmaciones!$B$2:$B$401,$B11,Afirmaciones!$E$2:$E$401,"hecho",Afirmaciones!$I$2:$I$401,"SIN-CITA") -> 0 | W11: =COUNTIFS(Afirmaciones!$A$2:$A$401,$A11,Afirmaciones!$B$2:$B$401,$B11,Afirmaciones!$E$2:$E$401,"hecho") -> 3 | X11: =COUNTIFS(Afirmaciones!$A$2:$A$401,$A11,Afirmaciones!$B$2:$B$401,$B11,Afirmaciones!$E$2:$E$401,"hecho",Afirmaciones!$I$2:$I$401,"SOSTENIDA") -> 0 | Y11: =IF($L11=0,"",IF($M11=0,IF($R11>0,0,2),IF(AND($N11=$M11,$P11+$Q11+$R11=0),2,IF($N11=0,0,1)))) -> 0 | Z11: =IF($L11=0,"",IF($B11="llm","N/A",IF($W11=0,"N/A",IF($X11=$W11,2,IF($X11=0,0,1))))) -> N/A | AA11: =IF($L11=0,"",IF(AND($P11+$Q11+$R11=0,$T11+$U11=0,$I11<>"SI"),"-",TRIM(IF($P11+$Q11+$R11>0,"CRITICA ","")&IF($T11+$U11>0,"RESPALDO ","")&IF($I11="SI","TRUNC","")))) -> CRITICA | AB11: =IF($L11=0,"",IF(AND($R11=0,$AF11=0,$AG11=0,$P11+$Q11=0,$T11+$U11+$V11=0),"OK",TRIM(IF($R11>0,"E0 ","")&IF($AF11>0,"E1 ","")&IF(OR($AG11>0,AND($P11+$Q11>0,$AF11=0)),"E2 ","")&IF($T11+$U11+$V11>0,"E3 ","")))) -> E2 | AC11: =IF($AB11="","",IF($AB11="OK","OK",LEFT($AB11,2))) -> E2 | AD11: =IF(OR($L11=0,$B11="llm",$W11=0),"-",$X11&"/"&$W11) -> - | AE11: =IF(OR($L11=0,$B11<>"rag",$M11=0),"-",SUMIFS(Hechos!$H$2:$H$201,Hechos!$A$2:$A$201,$A11)&"/"&$M11) -> - | AF11: =IF($B11="rag",SUMPRODUCT((Hechos!$A$2:$A$201=$A11)*(Hechos!$F$2:$F$201=0)*((Hechos!$E$2:$E$201="NO")+(Hechos!$E$2:$E$201="ALT-P")+(Hechos!$E$2:$E$201=""))),0) -> 0 | AG11: =IF($B11="rag",SUMPRODUCT((Hechos!$A$2:$A$201=$A11)*(Hechos!$F$2:$F$201=0)*((Hechos!$E$2:$E$201="SI")+(Hechos!$E$2:$E$201="ALT"))),$M11-$N11) -> 4 | AI11: 0 | N/A | E2
A12: p06 | B12: rag | C12: ES | D12: parcial | E12: ¿Qué sub-técnicas de intérpretes de comandos (T1059.*) usa Lazarus Group (G0032) según ATT&CK, y qué ataques ha realizado este grupo contra Ecuador? | F12: ATT&CK atribuye a Lazarus Group tres sub-técnicas de T1059: T1059.001 PowerShell, T1059.003 Windows Command Shell y T1059.005 Visual Basic. | G12: Ataques contra Ecuador: el documento de G0032 no menciona Ecuador (la única aparición de 'Ecuador' en todo el corpus está en T1480 Execution Guardrails, sin relación con Lazarus). | H12: No se proporciona información en los contextos sobre qué sub-técnicas de intérpretes de comandos (T1059.*) usa el Lazarus Group (G0032) o sobre ataques específicos que haya realizado contra Ecuador. Aunque se menciona que el Lazarus Group utiliza técnicas como T1059.003 Windows Command Shell y T1059.005 Visual Basic en el contexto de software como AuditCred y TYPEFRAME [1][3], no se especifica explícitamente el uso de sub-técnicas de T1059.* en general, ni se menciona cualquier actividad contra Ecuador. Además, no hay ninguna referencia en los contextos a ataques realizados por el Lazarus Group contra Ecuador. Por lo tanto, **no se puede responder con certeza** a la pregunta basándose únicamente en los contextos proporcionados. **Respuesta: No se puede determinar a partir de los contextos proporcionados.** | I12: NO | J12: TODA | K12: 3/3 | L12: =COUNTIFS(Afirmaciones!$A$2:$A$401,$A12,Afirmaciones!$B$2:$B$401,$B12) -> 3 | M12: =COUNTIFS(Hechos!$A$2:$A$201,$A12) -> 3 | N12: =IF($B12="rag",SUMIFS(Hechos!$F$2:$F$201,Hechos!$A$2:$A$201,$A12),SUMIFS(Hechos!$G$2:$G$201,Hechos!$A$2:$A$201,$A12)) -> 2 | O12: =IF($M12=0,"-",$N12&"/"&$M12) -> 2/3 | P12: =COUNTIFS(Afirmaciones!$A$2:$A$401,$A12,Afirmaciones!$B$2:$B$401,$B12,Afirmaciones!$E$2:$E$401,"hecho",Afirmaciones!$F$2:$F$401,"INCORRECTA") -> 0 | Q12: =COUNTIFS(Afirmaciones!$A$2:$A$401,$A12,Afirmaciones!$B$2:$B$401,$B12,Afirmaciones!$E$2:$E$401,"abstencion",Afirmaciones!$F$2:$F$401,"INCORRECTA") -> 1 | R12: =COUNTIFS(Afirmaciones!$A$2:$A$401,$A12,Afirmaciones!$B$2:$B$401,$B12,Afirmaciones!$E$2:$E$401,"hecho",Afirmaciones!$F$2:$F$401,"FUERA_REF",Afirmaciones!$H$2:$H$401,"no_resp") -> 0 | S12: =COUNTIFS(Afirmaciones!$A$2:$A$401,$A12,Afirmaciones!$B$2:$B$401,$B12,Afirmaciones!$E$2:$E$401,"hecho",Afirmaciones!$F$2:$F$401,"FUERA_REF") -> 0 | T12: =COUNTIFS(Afirmaciones!$A$2:$A$401,$A12,Afirmaciones!$B$2:$B$401,$B12,Afirmaciones!$E$2:$E$401,"hecho",Afirmaciones!$I$2:$I$401,"SIN-RESPALDO") -> 0 | U12: =COUNTIFS(Afirmaciones!$A$2:$A$401,$A12,Afirmaciones!$B$2:$B$401,$B12,Afirmaciones!$E$2:$E$401,"hecho",Afirmaciones!$I$2:$I$401,"CITA-X") -> 0 | V12: =COUNTIFS(Afirmaciones!$A$2:$A$401,$A12,Afirmaciones!$B$2:$B$401,$B12,Afirmaciones!$E$2:$E$401,"hecho",Afirmaciones!$I$2:$I$401,"SIN-CITA") -> 0 | W12: =COUNTIFS(Afirmaciones!$A$2:$A$401,$A12,Afirmaciones!$B$2:$B$401,$B12,Afirmaciones!$E$2:$E$401,"hecho") -> 1 | X12: =COUNTIFS(Afirmaciones!$A$2:$A$401,$A12,Afirmaciones!$B$2:$B$401,$B12,Afirmaciones!$E$2:$E$401,"hecho",Afirmaciones!$I$2:$I$401,"SOSTENIDA") -> 1 | Y12: =IF($L12=0,"",IF($M12=0,IF($R12>0,0,2),IF(AND($N12=$M12,$P12+$Q12+$R12=0),2,IF($N12=0,0,1)))) -> 1 | Z12: =IF($L12=0,"",IF($B12="llm","N/A",IF($W12=0,"N/A",IF($X12=$W12,2,IF($X12=0,0,1))))) -> 2 | AA12: =IF($L12=0,"",IF(AND($P12+$Q12+$R12=0,$T12+$U12=0,$I12<>"SI"),"-",TRIM(IF($P12+$Q12+$R12>0,"CRITICA ","")&IF($T12+$U12>0,"RESPALDO ","")&IF($I12="SI","TRUNC","")))) -> CRITICA | AB12: =IF($L12=0,"",IF(AND($R12=0,$AF12=0,$AG12=0,$P12+$Q12=0,$T12+$U12+$V12=0),"OK",TRIM(IF($R12>0,"E0 ","")&IF($AF12>0,"E1 ","")&IF(OR($AG12>0,AND($P12+$Q12>0,$AF12=0)),"E2 ","")&IF($T12+$U12+$V12>0,"E3 ","")))) -> E2 | AC12: =IF($AB12="","",IF($AB12="OK","OK",LEFT($AB12,2))) -> E2 | AD12: =IF(OR($L12=0,$B12="llm",$W12=0),"-",$X12&"/"&$W12) -> 1/1 | AE12: =IF(OR($L12=0,$B12<>"rag",$M12=0),"-",SUMIFS(Hechos!$H$2:$H$201,Hechos!$A$2:$A$201,$A12)&"/"&$M12) -> 2/3 | AF12: =IF($B12="rag",SUMPRODUCT((Hechos!$A$2:$A$201=$A12)*(Hechos!$F$2:$F$201=0)*((Hechos!$E$2:$E$201="NO")+(Hechos!$E$2:$E$201="ALT-P")+(Hechos!$E$2:$E$201=""))),0) -> 0 | AG12: =IF($B12="rag",SUMPRODUCT((Hechos!$A$2:$A$201=$A12)*(Hechos!$F$2:$F$201=0)*((Hechos!$E$2:$E$201="SI")+(Hechos!$E$2:$E$201="ALT"))),$M12-$N12) -> 1 | AI12: 1 | 2 | E2
A13: p06 | B13: llm | C13: ES | D13: parcial | E13: ¿Qué sub-técnicas de intérpretes de comandos (T1059.*) usa Lazarus Group (G0032) según ATT&CK, y qué ataques ha realizado este grupo contra Ecuador? | F13: ATT&CK atribuye a Lazarus Group tres sub-técnicas de T1059: T1059.001 PowerShell, T1059.003 Windows Command Shell y T1059.005 Visual Basic. | G13: Ataques contra Ecuador: el documento de G0032 no menciona Ecuador (la única aparición de 'Ecuador' en todo el corpus está en T1480 Execution Guardrails, sin relación con Lazarus). | H13: No se ha documentado oficialmente en el MITRE ATT&CK que el grupo Lazarus (G0032) haya utilizado específicamente sub-técnicas de intérpretes de comandos (T1059.*) como parte de sus actividades conocidas, ni se ha registrado un ataque directo contra Ecuador atribuido a este grupo en fuentes oficiales del MITRE ATT&CK. Además, el MITRE ATT&CK no proporciona una lista detallada de sub-técnicas (como T1059.001, T1059.002, etc.) que el grupo Lazarus haya utilizado en operaciones específicas, ni hay evidencia verificada de que el grupo haya atacado a Ecuador. Por lo tanto, **no se puede afirmar con certeza** que Lazarus haya usado sub-técnicas de intérpretes de comandos (T1059.*) o que haya realizado ataques contra Ecuador según el MITRE ATT&CK. **Respuesta final:** No hay evidencia oficial en el MITRE ATT&CK de que el grupo Lazarus (G0032) haya utilizado sub-técnicas de intérpretes de comandos (T1059.*) o haya realizado ataques contra Ecuador. | I13: NO | L13: =COUNTIFS(Afirmaciones!$A$2:$A$401,$A13,Afirmaciones!$B$2:$B$401,$B13) -> 2 | M13: =COUNTIFS(Hechos!$A$2:$A$201,$A13) -> 3 | N13: =IF($B13="rag",SUMIFS(Hechos!$F$2:$F$201,Hechos!$A$2:$A$201,$A13),SUMIFS(Hechos!$G$2:$G$201,Hechos!$A$2:$A$201,$A13)) -> 0 | O13: =IF($M13=0,"-",$N13&"/"&$M13) -> 0/3 | P13: =COUNTIFS(Afirmaciones!$A$2:$A$401,$A13,Afirmaciones!$B$2:$B$401,$B13,Afirmaciones!$E$2:$E$401,"hecho",Afirmaciones!$F$2:$F$401,"INCORRECTA") -> 1 | Q13: =COUNTIFS(Afirmaciones!$A$2:$A$401,$A13,Afirmaciones!$B$2:$B$401,$B13,Afirmaciones!$E$2:$E$401,"abstencion",Afirmaciones!$F$2:$F$401,"INCORRECTA") -> 0 | R13: =COUNTIFS(Afirmaciones!$A$2:$A$401,$A13,Afirmaciones!$B$2:$B$401,$B13,Afirmaciones!$E$2:$E$401,"hecho",Afirmaciones!$F$2:$F$401,"FUERA_REF",Afirmaciones!$H$2:$H$401,"no_resp") -> 0 | S13: =COUNTIFS(Afirmaciones!$A$2:$A$401,$A13,Afirmaciones!$B$2:$B$401,$B13,Afirmaciones!$E$2:$E$401,"hecho",Afirmaciones!$F$2:$F$401,"FUERA_REF") -> 0 | T13: =COUNTIFS(Afirmaciones!$A$2:$A$401,$A13,Afirmaciones!$B$2:$B$401,$B13,Afirmaciones!$E$2:$E$401,"hecho",Afirmaciones!$I$2:$I$401,"SIN-RESPALDO") -> 0 | U13: =COUNTIFS(Afirmaciones!$A$2:$A$401,$A13,Afirmaciones!$B$2:$B$401,$B13,Afirmaciones!$E$2:$E$401,"hecho",Afirmaciones!$I$2:$I$401,"CITA-X") -> 0 | V13: =COUNTIFS(Afirmaciones!$A$2:$A$401,$A13,Afirmaciones!$B$2:$B$401,$B13,Afirmaciones!$E$2:$E$401,"hecho",Afirmaciones!$I$2:$I$401,"SIN-CITA") -> 0 | W13: =COUNTIFS(Afirmaciones!$A$2:$A$401,$A13,Afirmaciones!$B$2:$B$401,$B13,Afirmaciones!$E$2:$E$401,"hecho") -> 2 | X13: =COUNTIFS(Afirmaciones!$A$2:$A$401,$A13,Afirmaciones!$B$2:$B$401,$B13,Afirmaciones!$E$2:$E$401,"hecho",Afirmaciones!$I$2:$I$401,"SOSTENIDA") -> 0 | Y13: =IF($L13=0,"",IF($M13=0,IF($R13>0,0,2),IF(AND($N13=$M13,$P13+$Q13+$R13=0),2,IF($N13=0,0,1)))) -> 0 | Z13: =IF($L13=0,"",IF($B13="llm","N/A",IF($W13=0,"N/A",IF($X13=$W13,2,IF($X13=0,0,1))))) -> N/A | AA13: =IF($L13=0,"",IF(AND($P13+$Q13+$R13=0,$T13+$U13=0,$I13<>"SI"),"-",TRIM(IF($P13+$Q13+$R13>0,"CRITICA ","")&IF($T13+$U13>0,"RESPALDO ","")&IF($I13="SI","TRUNC","")))) -> CRITICA | AB13: =IF($L13=0,"",IF(AND($R13=0,$AF13=0,$AG13=0,$P13+$Q13=0,$T13+$U13+$V13=0),"OK",TRIM(IF($R13>0,"E0 ","")&IF($AF13>0,"E1 ","")&IF(OR($AG13>0,AND($P13+$Q13>0,$AF13=0)),"E2 ","")&IF($T13+$U13+$V13>0,"E3 ","")))) -> E2 | AC13: =IF($AB13="","",IF($AB13="OK","OK",LEFT($AB13,2))) -> E2 | AD13: =IF(OR($L13=0,$B13="llm",$W13=0),"-",$X13&"/"&$W13) -> - | AE13: =IF(OR($L13=0,$B13<>"rag",$M13=0),"-",SUMIFS(Hechos!$H$2:$H$201,Hechos!$A$2:$A$201,$A13)&"/"&$M13) -> - | AF13: =IF($B13="rag",SUMPRODUCT((Hechos!$A$2:$A$201=$A13)*(Hechos!$F$2:$F$201=0)*((Hechos!$E$2:$E$201="NO")+(Hechos!$E$2:$E$201="ALT-P")+(Hechos!$E$2:$E$201=""))),0) -> 0 | AG13: =IF($B13="rag",SUMPRODUCT((Hechos!$A$2:$A$201=$A13)*(Hechos!$F$2:$F$201=0)*((Hechos!$E$2:$E$201="SI")+(Hechos!$E$2:$E$201="ALT"))),$M13-$N13) -> 3 | AI13: 0 | N/A | E2
